Workbook

Sheet traffic
A1: ngay | B1: nguon | C1: phien | D1: xem_san_pham | E1: them_gio | F1: bat_dau_thanh_toan | G1: don_hoan_tat | H1: doanh_thu
A2: 2026-06-01 | B2: organic | C2: 228 | D2: 96 | E2: 29 | F2: 18 | G2: 9 | H2: 3645000
A3: 2026-06-01 | B3: paid_search | C3: 148 | D3: 68 | E3: 18 | F3: 12 | G3: 5 | H3: 1810000
A4: 2026-06-01 | B4: social_paid | C4: 242 | D4: 67 | E4: 18 | F4: 10 | G4: 4 | H4: 1616000
A5: 2026-06-01 | B5: social_organic | C5: 75 | D5: 35 | E5: 11 | F5: 7 | G5: 1 | H5: 417000
A6: 2026-06-01 | B6: email | C6: 57 | D6: 39 | E6: 12 | F6: 7 | G6: 3 | H6: 1272000
A7: 2026-06-02 | B7: organic | C7: 193 | D7: 78 | E7: 24 | F7: 15 | G7: 7 | H7: 2492000
A8: 2026-06-02 | B8: paid_search | C8: 206 | D8: 98 | E8: 31 | F8: 19 | G8: 7 | H8: 2877000
A9: 2026-06-02 | B9: social_paid | C9: 253 | D9: 67 | E9: 21 | F9: 13 | G9: 4 | H9: 1416000
A10: 2026-06-02 | B10: social_organic | C10: 97 | D10: 39 | E10: 11 | F10: 6 | G10: 1 | H10: 324000
A11: 2026-06-02 | B11: email | C11: 82 | D11: 53 | E11: 17 | F11: 11 | G11: 5 | H11: 2270000
A12: 2026-06-03 | B12: organic | C12: 230 | D12: 100 | E12: 30 | F12: 18 | G12: 8 | H12: 4368000
A13: 2026-06-03 | B13: paid_search | C13: 218 | D13: 89 | E13: 30 | F13: 19 | G13: 6 | H13: 2892000
... A301: 2026-07-30 | B301: email | C301: 108 | D301: 65 | E301: 19 | F301: 11 | G301: 6 | H301: 2676000

Sheet ad_spend
A1: ngay | B1: kenh | C1: chien_dich | D1: hien_thi | E1: luot_nhap | F1: chi_phi | G1: chuyen_doi | H1: doanh_thu_quy_ket
A2: 2026-06-01 | B2: paid_search | C2: TK-thuong-hieu | D2: 11478 | E2: 950 | F2: 2687000 | G2: 55 | H2: 21450000
A3: 2026-06-01 | B3: paid_search | C3: TK-danh-muc | D3: 13565 | E3: 381 | F3: 1684000 | G3: 8 | H3: 3992000
A4: 2026-06-01 | B4: social_paid | C4: MXH-nhan-biet | D4: 21179 | E4: 217 | F4: 192000 | G4: 1 | H4: 389000
A5: 2026-06-01 | B5: social_paid | C5: MXH-tiep-thi-lai | D5: 29828 | E5: 545 | F5: 892000 | G5: 26 | H5: 11206000
A6: 2026-06-02 | B6: paid_search | C6: TK-thuong-hieu | D6: 10376 | E6: 840 | F6: 2380000 | G6: 59 | H6: 30385000
A7: 2026-06-02 | B7: paid_search | C7: TK-danh-muc | D7: 13677 | E7: 417 | F7: 1597000 | G7: 12 | H7: 6924000
A8: 2026-06-02 | B8: social_paid | C8: MXH-nhan-biet | D8: 16098 | E8: 124 | F8: 116000 | G8: 1 | H8: 550000
A9: 2026-06-02 | B9: social_paid | C9: MXH-tiep-thi-lai | D9: 29389 | E9: 679 | F9: 1139000 | G9: 27 | H9: 11745000
A10: 2026-06-03 | B10: paid_search | C10: TK-thuong-hieu | D10: 7352 | E10: 655 | F10: 1791000 | G10: 37 | H10: 19758000
A11: 2026-06-03 | B11: paid_search | C11: TK-danh-muc | D11: 8816 | E11: 314 | F11: 1334000 | G11: 7 | H11: 3234000
A12: 2026-06-03 | B12: social_paid | C12: MXH-nhan-biet | D12: 24566 | E12: 215 | F12: 186000 | G12: 1 | H12: 492000
A13: 2026-06-03 | B13: social_paid | C13: MXH-tiep-thi-lai | D13: 20195 | E13: 452 | F13: 736000 | G13: 21 | H13: 10206000
... A241: 2026-07-30 | B241: social_paid | C241: MXH-tiep-thi-lai | D241: 13849 | E241: 306 | F241: 447000 | G241: 16 | H241: 8016000

Sheet customers
A1: ma_khach | B1: ngay_dau | C1: so_don_12thang | D1: doanh_thu_12thang | E1: nhom_hang_chinh | F1: kenh_thu_hut | G1: da_dang_ky_thu
A2: KH0001 | B2: 2025-08-13 | C2: 1 | D2: 663000 | E2: Mỹ thuật | F2: email | G2: Khong
A3: KH0002 | B3: 2025-10-19 | C3: 1 | D3: 291000 | E3: Ba lô & túi | F3: social_paid | G3: Co
A4: KH0003 | B4: 2025-11-24 | C4: 6 | D4: 2832000 | E4: Dụng cụ học tập | F4: organic | G4: Khong
A5: KH0004 | B5: 2026-05-31 | C5: 5 | D5: 1445000 | E5: Ba lô & túi | F5: email | G5: Khong
A6: KH0005 | B6: 2025-08-26 | C6: 4 | D6: 1144000 | E6: Mỹ thuật | F6: paid_search | G6: Khong
A7: KH0006 | B7: 2026-02-20 | C7: 5 | D7: 2400000 | E7: Vở & sổ | F7: paid_search | G7: Khong
A8: KH0007 | B8: 2026-02-08 | C8: 10 | D8: 7570000 | E8: Vở & sổ | F8: organic | G8: Khong
A9: KH0008 | B9: 2026-01-01 | C9: 10 | D9: 3630000 | E9: Mỹ thuật | F9: social_organic | G9: Co
A10: KH0009 | B10: 2025-11-02 | C10: 2 | D10: 540000 | E10: Dụng cụ học tập | F10: social_paid | G10: Co
A11: KH0010 | B11: 2026-05-24 | C11: 1 | D11: 580000 | E11: Ba lô & túi | F11: organic | G11: Co
A12: KH0011 | B12: 2025-11-20 | C12: 2 | D12: 838000 | E12: Mỹ thuật | F12: social_organic | G12: Co
A13: KH0012 | B13: 2025-09-08 | C13: 1 | D13: 282000 | E13: Ba lô & túi | F13: social_paid | G13: Co
... A301: KH0300 | B301: 2025-08-15 | C301: 3 | D301: 885000 | E301: Bút viết | F301: paid_search | G301: Khong

Sheet products
A1: sku | B1: ten_san_pham | C1: danh_muc | D1: gia_ban | E1: gia_von | F1: ton_kho | G1: trong_luong_g | H1: kiem_dinh_an_toan | I1: mo_ta_ngan
A2: SKU001 | B2: Bút bi gel 0.5mm | C2: Bút viết | D2: 58000 | E2: 39000 | F2: 97 | G2: 767 | H2: Khong | I2: Hang chinh hang | J2: co hoa don. Bút bi gel 0.5mm thuoc nhom Bút viết.
A3: SKU002 | B3: Bút chì gỗ HB | C3: Bút viết | D3: 290000 | E3: 196000 | F3: 155 | G3: 435 | H3: Khong | I3: Hang chinh hang | J3: co hoa don. Bút chì gỗ HB thuoc nhom Bút viết.
A4: SKU003 | B4: Bút highlight 5 màu | C4: Bút viết | D4: 220000 | E4: 129000 | F4: 146 | G4: 222 | H4: Co | I4: Hang chinh hang | J4: co hoa don. Bút highlight 5 màu thuoc nhom Bút viết.
A5: SKU004 | B5: Bút lông kim 0.4mm | C5: Bút viết | D5: 35000 | E5: 24000 | F5: 172 | G5: 793 | H5: Co | I5: Hang chinh hang | J5: co hoa don. Bút lông kim 0.4mm thuoc nhom Bút viết.
A6: SKU005 | B6: Bút xoá nước 8ml | C6: Bút viết | D6: 290000 | E6: 181000 | F6: 150 | G6: 203 | H6: Co | I6: Hang chinh hang | J6: co hoa don. Bút xoá nước 8ml thuoc nhom Bút viết.
A7: SKU006 | B7: Ruột bút gel 0.5mm | C7: Bút viết | D7: 220000 | E7: 157000 | F7: 35 | G7: 840 | H7: Khong | I7: Hang chinh hang | J7: co hoa don. Ruột bút gel 0.5mm thuoc nhom Bút viết.
A8: SKU007 | B8: Bút chì bấm 0.7mm | C8: Bút viết | D8: 75000 | E8: 52000 | F8: 173 | G8: 178 | H8: Co | I8: Hang chinh hang | J8: co hoa don. Bút chì bấm 0.7mm thuoc nhom Bút viết.
A9: SKU008 | B9: Bút máy luyện chữ | C9: Bút viết | D9: 45000 | E9: 32000 | F9: 114 | G9: 186 | H9: Co | I9: Hang chinh hang | J9: co hoa don. Bút máy luyện chữ thuoc nhom Bút viết.
A10: SKU009 | B10: Vở kẻ ngang 200 trang | C10: Vở & sổ | D10: 95000 | E10: 56000 | F10: 162 | G10: 597 | H10: Co | I10: Hang chinh hang | J10: co hoa don. Vở kẻ ngang 200 trang thuoc nhom Vở & sổ.
A11: SKU010 | B11: Vở ô ly lớp 1 | C11: Vở & sổ | D11: 165000 | E11: 120000 | F11: 84 | G11: 75 | H11: Khong | I11: Hang chinh hang | J11: co hoa don. Vở ô ly lớp 1 thuoc nhom Vở & sổ.
A12: SKU011 | B12: Sổ tay bìa cứng A5 | C12: Vở & sổ | D12: 290000 | E12: 167000 | F12: 196 | G12: 150 | H12: Khong | I12: Hang chinh hang | J12: co hoa don. Sổ tay bìa cứng A5 thuoc nhom Vở & sổ.
A13: SKU012 | B13: Vở vẽ A4 không dòng | C13: Vở & sổ | D13: 35000 | E13: 20000 | F13: 108 | G13: 115 | H13: Khong | I13: Hang chinh hang | J13: co hoa don. Vở vẽ A4 không dòng thuoc nhom Vở & sổ.
... A41: SKU040 | B41: Bộ tô tượng thạch cao | C41: Mỹ thuật | D41: 290000 | E41: 184000 | F41: 71 | G41: 184 | H41: Co | I41: Hang chinh hang | J41: co hoa don. Bộ tô tượng thạch cao thuoc nhom Mỹ thuật.

Sheet Tong_hop
A1: 5.1 PHỄU CHUYỂN ĐỔI THEO NGUỒN LƯU LƯỢNG
A3: Nguồn | B3: Tổng Phiên | C3: Xem SP | D3: Thêm giỏ | E3: Bắt đầu TT | F3: Đơn hoàn tất | G3: Doanh thu | H3: Tỷ lệ xem SP | I3: Tỷ lệ thêm giỏ | J3: Tỷ lệ bắt đầu TT | K3: Tỷ lệ hoàn tất TT | L3: CR toàn phễu | M3: AOV
A4: organic | B4: =SUMIF(traffic!$B:$B,$A4,traffic!$C:$C) -> 16369 | C4: =SUMIF(traffic!$B:$B,$A4,traffic!$D:$D) -> 7168 | D4: =SUMIF(traffic!$B:$B,$A4,traffic!$E:$E) -> 2130 | E4: =SUMIF(traffic!$B:$B,$A4,traffic!$F:$F) -> 1272 | F4: =SUMIF(traffic!$B:$B,$A4,traffic!$G:$G) -> 618 | G4: =SUMIF(traffic!$B:$B,$A4,traffic!$H:$H) -> 267697000 | H4: =C4/B4 -> 0.43790091 | I4: =D4/C4 -> 0.29715402 | J4: =E4/D4 -> 0.5971831 | K4: =F4/E4 -> 0.48584906 | L4: =F4/B4 -> 0.037754292 | M4: =G4/F4 -> 433166.67
A5: paid_search | B5: =SUMIF(traffic!$B:$B,$A5,traffic!$C:$C) -> 13512 | C5: =SUMIF(traffic!$B:$B,$A5,traffic!$D:$D) -> 6037 | D5: =SUMIF(traffic!$B:$B,$A5,traffic!$E:$E) -> 1809 | E5: =SUMIF(traffic!$B:$B,$A5,traffic!$F:$F) -> 1088 | F5: =SUMIF(traffic!$B:$B,$A5,traffic!$G:$G) -> 415 | G5: =SUMIF(traffic!$B:$B,$A5,traffic!$H:$H) -> 187261000 | H5: =C5/B5 -> 0.44678804 | I5: =D5/C5 -> 0.29965215 | J5: =E5/D5 -> 0.60143726 | K5: =F5/E5 -> 0.38143382 | L5: =F5/B5 -> 0.03071344 | M5: =G5/F5 -> 451231.33
A6: social_paid | B6: =SUMIF(traffic!$B:$B,$A6,traffic!$C:$C) -> 19693 | C6: =SUMIF(traffic!$B:$B,$A6,traffic!$D:$D) -> 5570 | D6: =SUMIF(traffic!$B:$B,$A6,traffic!$E:$E) -> 1707 | E6: =SUMIF(traffic!$B:$B,$A6,traffic!$F:$F) -> 1012 | F6: =SUMIF(traffic!$B:$B,$A6,traffic!$G:$G) -> 279 | G6: =SUMIF(traffic!$B:$B,$A6,traffic!$H:$H) -> 127702000 | H6: =C6/B6 -> 0.28284162 | I6: =D6/C6 -> 0.3064632 | J6: =E6/D6 -> 0.59285296 | K6: =F6/E6 -> 0.2756917 | L6: =F6/B6 -> 0.014167471 | M6: =G6/F6 -> 457713.26
A7: social_organic | B7: =SUMIF(traffic!$B:$B,$A7,traffic!$C:$C) -> 6866 | C7: =SUMIF(traffic!$B:$B,$A7,traffic!$D:$D) -> 3010 | D7: =SUMIF(traffic!$B:$B,$A7,traffic!$E:$E) -> 916 | E7: =SUMIF(traffic!$B:$B,$A7,traffic!$F:$F) -> 547 | F7: =SUMIF(traffic!$B:$B,$A7,traffic!$G:$G) -> 74 | G7: =SUMIF(traffic!$B:$B,$A7,traffic!$H:$H) -> 34165000 | H7: =C7/B7 -> 0.43839208 | I7: =D7/C7 -> 0.30431894 | J7: =E7/D7 -> 0.59716157 | K7: =F7/E7 -> 0.13528336 | L7: =F7/B7 -> 0.010777745 | M7: =G7/F7 -> 461689.19
A8: email | B8: =SUMIF(traffic!$B:$B,$A8,traffic!$C:$C) -> 5344 | C8: =SUMIF(traffic!$B:$B,$A8,traffic!$D:$D) -> 3356 | D8: =SUMIF(traffic!$B:$B,$A8,traffic!$E:$E) -> 1012 | E8: =SUMIF(traffic!$B:$B,$A8,traffic!$F:$F) -> 616 | F8: =SUMIF(traffic!$B:$B,$A8,traffic!$G:$G) -> 274 | G8: =SUMIF(traffic!$B:$B,$A8,traffic!$H:$H) -> 123714000 | H8: =C8/B8 -> 0.62799401 | I8: =D8/C8 -> 0.30154946 | J8: =E8/D8 -> 0.60869565 | K8: =F8/E8 -> 0.44480519 | L8: =F8/B8 -> 0.051272455 | M8: =G8/F8 -> 451510.95
A9: TỔNG CỘNG | B9: =SUM(B4:B8) -> 61784 | C9: =SUM(C4:C8) -> 25141 | D9: =SUM(D4:D8) -> 7574 | E9: =SUM(E4:E8) -> 4535 | F9: =SUM(F4:F8) -> 1660 | G9: =SUM(G4:G8) -> 740539000 | H9: =C9/B9 -> 0.40691765 | I9: =D9/C9 -> 0.30126089 | J9: =E9/D9 -> 0.59875891 | K9: =F9/E9 -> 0.3660419 | L9: =F9/B9 -> 0.026867797 | M9: =G9/F9 -> 446107.83
A11: 5.2 Chọn điểm can thiệp bằng số tuyệt đối
A13: Bước phễu | B13: Số nguồn thực tế | C13: Tỷ lệ hiện tại | D13: Giải pháp | E13: Delta tỷ lệ | F13: Số đơn tăng thêm | G13: Chi phí dự kiến | H13: Lợi nhuận ròng
A14: Phiên -> Xem SP | B14: =B9 -> 61784 | C14: =H9 -> 0.40691765 | D14: Tối ưu hình ảnh SP, mô tả hấp dẫn | E14: 0.04 | F14: =B14*E14*I9*J9*K9 -> 163.17798 | G14: 500000 | H14: =F14*M9-G14 -> 72294975
A15: Xem SP->Thêm giỏ | B15: =C9 -> 25141 | C15: =I9 -> 0.30126089 | D15: Gợi ý sản phẩm liên quan, ưu đãi thêm giỏ hàng | E15: 0.04 | F15: =B15*E15*J9*K9 -> 220.40697 | G15: 300000 | H15: =F15*M9-G15 -> 98025276
A16: Thêm giỏ -> Bắt đầu TT | B16: =D9 -> 7574 | C16: =J9 -> 0.59875891 | D16: Đơn giản hóa quy trình thanh toán | E16: 0.05 | F16: =B16*E16*K9 -> 138.62007 | G16: 200000 | H16: =F16*M9-G16 -> 61639497
A17: Bắt đầu TT -> Đơn hoàn tất | B17: =E9 -> 4535 | C17: =K9 -> 0.3660419 | D17: Email nhắc nhở hoàn tất, giảm giá vận chuyển | E17: 0.05 | F17: =B17*E17 -> 226.75 | G17: 100000 | H17: =F17*M9-G17 -> 1.0105495e+08
A19: 5.3 BA CHỈ SỐ KINH TẾ
A21: a) ROAS THEO CHIẾN DỊCH
A22: Chiến dịch | B22: Kênh | C22: Chi phí (ad_spend) | D22: Doanh thu quy kết | E22: ROAS | F22: Đánh giá
A23: TK-thuong-hieu | B23: paid_search | C23: =SUMPRODUCT((ad_spend!$C$2:$C$241=A23)*ad_spend!$F$2:$F$241) -> 149645000 | D23: =SUMPRODUCT((ad_spend!$C$2:$C$241=A23)*ad_spend!$H$2:$H$241) -> 1492429000 | E23: =IF(C23=0,"",D23/C23) -> 9.9731297 | F23: =IF(E23>=3,"Tot",IF(E23>=1,"Chap nhan","CAN TAT")) -> Tot
A24: TK-danh-muc | B24: paid_search | C24: =SUMPRODUCT((ad_spend!$C$2:$C$241=A24)*ad_spend!$F$2:$F$241) -> 85747000 | D24: =SUMPRODUCT((ad_spend!$C$2:$C$241=A24)*ad_spend!$H$2:$H$241) -> 260240000 | E24: =IF(C24=0,"",D24/C24) -> 3.034975 | F24: =IF(E24>=3,"Tot",IF(E24>=1,"Chap nhan","CAN TAT")) -> Tot
A25: MXH-nhan-biet | B25: social_paid | C25: =SUMPRODUCT((ad_spend!$C$2:$C$241=A25)*ad_spend!$F$2:$F$241) -> 10646000 | D25: =SUMPRODUCT((ad_spend!$C$2:$C$241=A25)*ad_spend!$H$2:$H$241) -> 32913000 | E25: =IF(C25=0,"",D25/C25) -> 3.0915837 | F25: =IF(E25>=3,"Tot",IF(E25>=1,"Chap nhan","CAN TAT")) -> Tot
A26: MXH-tiep-thi-lai | B26: social_paid | C26: =SUMPRODUCT((ad_spend!$C$2:$C$241=A26)*ad_spend!$F$2:$F$241) -> 45208000 | D26: =SUMPRODUCT((ad_spend!$C$2:$C$241=A26)*ad_spend!$H$2:$H$241) -> 643328000 | E26: =IF(C26=0,"",D26/C26) -> 14.230402 | F26: =IF(E26>=3,"Tot",IF(E26>=1,"Chap nhan","CAN TAT")) -> Tot
A28: b) CAC THEO KÊNH
A29: Kênh | B29: Tổng chi phí | C29: Tổng chuyển đổi | D29: CAC | E29: Ghi chú
A30: paid_search | B30: =SUMPRODUCT((ad_spend!$B$2:$B$241="paid_search")*ad_spend!$F$2:$F$241) -> 235392000 | C30: =SUMPRODUCT((ad_spend!$B$2:$B$241="paid_search")*ad_spend!$G$2:$G$241) -> 3778 | D30: =IF(C30=0,"",B30/C30) -> 62305.982
A31: social_paid | B31: =SUMPRODUCT((ad_spend!$B$2:$B$241="social_paid")*ad_spend!$F$2:$F$241) -> 55854000 | C31: =SUMPRODUCT((ad_spend!$B$2:$B$241="social_paid")*ad_spend!$G$2:$G$241) -> 1409 | D31: =IF(C31=0,"",B31/C31) -> 39640.88
A32: organic, social_organic, email | E32: Không phát sinh chi phí trực tiếp trong ad_spend
A34: c) GIÁ TRỊ VÒNG ĐỜI (LTV)
A35: AOV (Gía trị đơn TB) | B35: =SUM(customers!$D$2:$D$301)/SUM(customers!$C$2:$C$301) -> 434252.43
A36: Số đơn/năm (TB môĩ KH) | B36: =SUM(customers!$C$2:$C$301)/300 -> 4.45
A37: Số năm gắn bó (giả định) | B37: 1.5 | C37: Giả định: 1.5 năm dựa trên tỷ lệ KH mua lại >1 đơn
A38: Tỷ lệ LN gộp (weighted by doanh thu) | B38: =SUMPRODUCT(((products!$D$2:$D$41-products!$E$2:$E$41)/products!$D$2:$D$41)*products!$D$2:$D$41)/SUM(products!$D$2:$D$41) -> 0.34549581
A39: LTV = AOV × Số đơn/năm × Số năm × Tỷ lệ LN | B39: =B35*B36*B37*B38 -> 1001466.2
A41: SO SANH CAC VS LTV
A42: Kênh | B42: CAC | C42: LTV | D42: Chênh lệch (LTV - CAC) | E42: Kết luận
A43: paid_search | B43: =D30 -> 62305.982 | C43: =B39 -> 1001466.2 | D43: =C43-B43 -> 939160.27 | E43: =IF(B43>C43, "LỖ - CAC > LTV, dừng đổ tiền", "CÓ LỜI - CAC < LTV") -> CÓ LỜI - CAC < LTV
A44: social_paid | B44: =D31 -> 39640.88 | C44: =B39 -> 1001466.2 | D44: =C44-B44 -> 961825.37 | E44: =IF(B44>C44,"LO - CAC > LTV, dừng đổ tiền","CÓ LỜI - CAC < LTV") -> CÓ LỜI - CAC < LTV
A46: 5.4 MA TRẬN GIÁ TRỊ VÀ TẦN SUẤT
A48: Ngưỡng giá trị (Median doanh thu) | B48: =MEDIAN(customers!$D$2:$D$301) -> 1340500
A49: Ngưỡng tần suất (Median so don) | B49: =MEDIAN(customers!$C$2:$C$301) -> 3
A51: Nhóm KH | B51: Số lượng | C51: Tổng doanh thu | D51: TB doanh thu/KH | E51: Hành động CSKH
...
